Workbook

Sheet Inicio
A1: Taller de Mollier · Libro de análisis del aprendizaje
A3: Propósito | B3: Registrar los resultados del Taller de Mollier (evaluaciones y práctica) y localizar en qué competencias, ítems, refrigerantes y tipos de error tienen dificultades los estudiantes de ingeniería.
A4: Modo automático | B4: Si publicaste la aplicación con Google Apps Script desde este libro (versión Google Sheets), los resultados llegan solos a Datos_problemas, Datos_items y Comprobantes; omite los pasos 1 a 3.
A5: Paso 1 | B5: Pide a cada estudiante el comprobante completo (incluye la línea DATOS y el código de verificación).
A6: Paso 2 | B6: En la aplicación abre «Panel docente: procesar comprobantes», pega todos los comprobantes juntos y pulsa «Procesar comprobantes».
A7: Paso 3 | B7: Pulsa «Copiar filas de Datos_problemas» y pega en la celda A1 de la hoja Datos_problemas (con encabezados). Repite con «Copiar filas de Datos_items» en la celda A1 de Datos_items.
A8: Agregar más datos | B8: Para sumar otro grupo o momento, desmarca «Incluir encabezados» en el panel y pega debajo de la última fila con datos. No borres la columna gris «aux_indice_alumno».
A9: Separador decimal | B9: Los datos usan punto decimal (formato de México). Si tu Excel está configurado con coma decimal, cambia temporalmente la configuración regional o importa el CSV indicando punto como separador.
A10: Paso 4 | B10: Revisa Analisis_grupo (filtros en celdas amarillas) y Por_alumno. Los colores van de rojo (bajo acierto o muchos errores) a verde.
A11: Celdas que puedes editar | B11: Solo las celdas amarillas con texto azul: filtros y umbrales en Analisis_grupo. Todo lo demás son datos pegados o fórmulas.
A12: Capacidad | B12: Las fórmulas cubren 2999 problemas en Datos_problemas y cualquier cantidad de filas en Datos_items. Por_alumno lista hasta 300 estudiantes.
A13: Ética | B13: La columna «consentimiento» indica si el estudiante aceptó el uso anónimo de sus datos. Para publicar, filtra consentimiento = Sí y sustituye nombre y matrícula por un código.
A14: Referencias | B14: Hojas Diccionario (qué significa cada columna), Matriz_Q (qué competencia evalúa cada ítem) y Catalogo_errores (errores tipificados y sugerencia didáctica).

Sheet Datos_problemas
A1: id_registro | B1: matricula | C1: nombre | D1: grupo | E1: momento | F1: modo | G1: consentimiento | H1: clave | I1: fecha | J1: hora | K1: version_app | L1: nivel | M1: nivel_nombre | N1: num_problema | O1: semilla | P1: refrigerante | Q1: familia_refrigerante | R1: clase_seguridad | S1: zeotropico | T1: escenario | U1: ciudad | V1: To_C | W1: Tk_C | X1: relacion_compresion | Y1: tiempo_s | Z1: n_colocaciones | AA1: n_ediciones_respuesta | AB1: n_cambios_isolineas | AC1: puntaje_colocacion_pct | AD1: puntaje_calculos_pct | AE1: calificacion | AF1: items_correctos | AG1: items_total | AH1: errores_lectura | AI1: errores_calculo | AJ1: errores_conceptuales | AK1: errores_arrastrados | AL1: sin_respuesta | AM1: codigos_error | AN1: competencia_mas_debil | AO1: comprobaciones_respuestas | AP1: comprobaciones_puntos | AQ1: pistas_vistas | AR1: valores_revelados | AS1: solucion_vista | AT1: puntos_correctos_vistos | AU1: resuelto_en_practica | AV1: aux_indice_alumno
AV2: =IF(B2="","",IF(COUNTIF($B$2:B2,B2)=1,MAX($AV$1:AV1)+1,""))
AV3: =IF(B3="","",IF(COUNTIF($B$2:B3,B3)=1,MAX($AV$1:AV2)+1,""))
AV4: =IF(B4="","",IF(COUNTIF($B$2:B4,B4)=1,MAX($AV$1:AV3)+1,""))
AV5: =IF(B5="","",IF(COUNTIF($B$2:B5,B5)=1,MAX($AV$1:AV4)+1,""))
AV6: =IF(B6="","",IF(COUNTIF($B$2:B6,B6)=1,MAX($AV$1:AV5)+1,""))
AV7: =IF(B7="","",IF(COUNTIF($B$2:B7,B7)=1,MAX($AV$1:AV6)+1,""))
AV8: =IF(B8="","",IF(COUNTIF($B$2:B8,B8)=1,MAX($AV$1:AV7)+1,""))
AV9: =IF(B9="","",IF(COUNTIF($B$2:B9,B9)=1,MAX($AV$1:AV8)+1,""))
AV10: =IF(B10="","",IF(COUNTIF($B$2:B10,B10)=1,MAX($AV$1:AV9)+1,""))
AV11: =IF(B11="","",IF(COUNTIF($B$2:B11,B11)=1,MAX($AV$1:AV10)+1,""))
AV12: =IF(B12="","",IF(COUNTIF($B$2:B12,B12)=1,MAX($AV$1:AV11)+1,""))
AV13: =IF(B13="","",IF(COUNTIF($B$2:B13,B13)=1,MAX($AV$1:AV12)+1,""))
... AV3000: =IF(B3000="","",IF(COUNTIF($B$2:B3000,B3000)=1,MAX($AV$1:AV2999)+1,""))

Sheet Datos_items
A1: id_registro | B1: matricula | C1: grupo | D1: momento | E1: modo | F1: fecha | G1: nivel | H1: num_problema | I1: refrigerante | J1: familia_refrigerante | K1: zeotropico | L1: item | M1: descripcion_item | N1: tipo_item | O1: competencia | P1: competencia_nombre | Q1: valor_alumno | R1: valor_esperado | S1: unidad | T1: P_alumno_bar | U1: P_esperado_bar | V1: error_abs | W1: error_rel_pct | X1: tolerancia | Y1: correcto | Z1: puntaje_item | AA1: codigo_error | AB1: descripcion_error | AC1: intentos_practica

Sheet Diccionario
A1: Diccionario de datos
A3: Hoja | B3: Columna | C3: Tipo / valores | D3: Descripción | E3: Ejemplo | F3: Uso en el análisis
A4: Datos_problemas | B4: id_registro | C4: Texto | D4: Identificador único del problema resuelto: matrícula-modo-fecha-código-número. | E4: 2345678-P-2026-10-02-0QFM-1 | F4: Llave para unir con Datos_items.
A5: Datos_problemas | B5: matricula | C5: Texto | D5: Matrícula del estudiante. | E5: 2345678 | F5: Seguimiento individual y pre/post.
A6: Datos_problemas | B6: nombre | C6: Texto | D6: Nombre completo tal como lo escribió el estudiante. | E6: Pérez López Ana | F6: Solo identificación; anonimizar antes de publicar.
A7: Datos_problemas | B7: grupo | C7: Texto | D7: Grupo escolar. | E7: 5A | F7: Comparar grupos.
A8: Datos_problemas | B8: momento | C8: Diagnóstico · Formativa · Final · Práctica | D8: Momento de aplicación elegido por el estudiante según tu indicación. | E8: Diagnóstico | F8: Diseño pretest–postest y ganancia normalizada.
A9: Datos_problemas | B9: modo | C9: Evaluación · Práctica | D9: Si el registro viene de una evaluación calificada o de la práctica con retroalimentación. | E9: Evaluación | F9: Separar evaluación de aprendizaje en proceso.
A10: Datos_problemas | B10: consentimiento | C10: Sí · No | D10: El estudiante aceptó el uso anónimo de sus datos en investigación. | E10: Sí | F10: Filtro ético obligatorio para publicar.
A11: Datos_problemas | B11: clave | C11: Texto | D11: Clave de evaluación; con la misma clave todos reciben los mismos problemas. | E11: IM-G2 | F11: Comparar alumnos con problemas idénticos.
A12: Datos_problemas | B12: fecha | C12: AAAA-MM-DD | D12: Fecha de entrega. | E12: 2026-10-02 | F12: Series de tiempo.
A13: Datos_problemas | B13: hora | C13: HH:MM | D13: Hora de entrega (hora local del equipo). | E13: 10:45
A14: Datos_problemas | B14: version_app | C14: Texto | D14: Versión de la aplicación. | E14: 2.0 | F14: Controlar cambios de instrumento.
A15: Datos_problemas | B15: nivel | C15: 1 · 2 · 3 | D15: Nivel del problema: 1 ciclo ideal, 2 ciclo real, 3 con rendimiento isentrópico y caudal. | E15: 2 | F15: Dificultad del ítem.
A16: Datos_problemas | B16: nivel_nombre | C16: Texto | D16: Nombre del nivel. | E16: Intermedio
A17: Datos_problemas | B17: num_problema | C17: Entero | D17: Posición del problema dentro de la evaluación o de la sesión. | E17: 1 | F17: Efecto de fatiga o de aprendizaje dentro de la sesión.
A18: Datos_problemas | B18: semilla | C18: Entero | D18: Número del problema; permite reproducirlo exactamente. | E18: 48213 | F18: Revisar el enunciado exacto.
A19: Datos_problemas | B19: refrigerante | C19: Texto | D19: Refrigerante del problema. | E19: R-448A | F19: Dificultad por refrigerante.
A20: Datos_problemas | B20: familia_refrigerante | C20: Texto | D20: HFC, HFO, HCFO, hidrocarburo, natural inorgánico o mezcla. | E20: Mezcla HFC/HFO zeotrópica | F20: Efecto del tipo de fluido.
A21: Datos_problemas | B21: clase_seguridad | C21: A1 · A2L · A3 · B2L | D21: Clasificación ISO 817 / ASHRAE 34. | E21: A1 | F21: Vincular con contenidos de normativa.
A22: Datos_problemas | B22: zeotropico | C22: Sí · No | D22: Si la mezcla tiene deslizamiento de temperatura. | E22: Sí | F22: Dificultad adicional de las mezclas zeotrópicas.
A23: Datos_problemas | B23: escenario | C23: Texto | D23: Aplicación del problema (cámara de carnes, chiller, minisplit…). | E23: cámara de productos congelados | F23: Transferencia a contextos.
A24: Datos_problemas | B24: ciudad | C24: Texto | D24: Ciudad que fija la temperatura exterior de proyecto. | E24: Hermosillo
A25: Datos_problemas | B25: To_C | C25: °C | D25: Temperatura de evaporación correcta del problema. | E25: -28 | F25: Condición de operación.
A26: Datos_problemas | B26: Tk_C | C26: °C | D26: Temperatura de condensación correcta del problema. | E26: 54 | F26: Condición de operación.
A27: Datos_problemas | B27: relacion_compresion | C27: Adimensional | D27: Pk/Po del problema. | E27: 6.8 | F27: Dificultad por condiciones extremas.
A28: Datos_problemas | B28: tiempo_s | C28: Segundos | D28: Tiempo desde que se abrió el problema hasta la entrega (evaluación) o hasta el último registro (práctica). | E28: 612 | F28: Esfuerzo; relación tiempo–desempeño.
A29: Datos_problemas | B29: n_colocaciones | C29: Entero | D29: Número de clics para colocar o recolocar puntos en el diagrama. | E29: 9 | F29: Ensayo y error en la representación gráfica.
A30: Datos_problemas | B30: n_ediciones_respuesta | C30: Entero | D30: Número de veces que se modificó alguna respuesta numérica. | E30: 14 | F30: Incertidumbre o autocorrección.
A31: Datos_problemas | B31: n_cambios_isolineas | C31: Entero | D31: Veces que se mostraron u ocultaron familias de líneas. | E31: 2 | F31: Estrategia de lectura del diagrama.
A32: Datos_problemas | B32: puntaje_colocacion_pct | C32: 0–100 | D32: Porcentaje obtenido en la colocación de puntos (cada punto vale 1; 0.5 si solo acierta P o h). | E32: 80 | F32: Dominio de la representación gráfica.
A33: Datos_problemas | B33: puntaje_calculos_pct | C33: 0–100 | D33: Porcentaje de lecturas y cálculos correctos. | E33: 66.7 | F33: Dominio numérico.
A34: Datos_problemas | B34: calificacion | C34: 0–10 | D34: 0.4 × colocación + 0.6 × cálculos, escala 10. | E34: 7.2 | F34: Variable de desempeño global.
A35: Datos_problemas | B35: items_correctos | C35: Entero | D35: Ítems correctos (puntos y respuestas). | E35: 14
A36: Datos_problemas | B36: items_total | C36: Entero | D36: Ítems evaluados en el problema. | E36: 20
A37: Datos_problemas | B37: errores_lectura | C37: Entero | D37: Ítems con código LEC: lectura imprecisa del diagrama. | E37: 2 | F37: Precisión de lectura.
A38: Datos_problemas | B38: errores_calculo | C38: Entero | D38: Ítems con código CAL: cálculo impreciso. | E38: 0 | F38: Precisión aritmética.
A39: Datos_problemas | B39: errores_conceptuales | C39: Entero | D39: Ítems con códigos E01–E14 (concepciones erróneas identificadas). | E39: 3 | F39: Indicador principal de dificultad conceptual.
A40: Datos_problemas | B40: errores_arrastrados | C40: Entero | D40: Ítems con código ARR: el procedimiento es correcto pero parte de un dato previo erróneo. | E40: 2 | F40: Separar dominio procedimental de errores previos.
A41: Datos_problemas | B41: sin_respuesta | C41: Entero | D41: Ítems sin contestar. | E41: 1 | F41: Omisión.
...

Sheet Matriz_Q
A1: Matriz Q: qué competencia evalúa cada ítem
A3: Código | B3: Competencia | C3: Descripción operativa
A4: C1 | B4: Condiciones de operación (To, Tk) | C4: Obtiene To y Tk a partir de la temperatura de conservación, el salto del evaporador, la temperatura exterior y el salto del condensador.
A5: C2 | B5: Presiones de saturación | C5: Lee en el diagrama la presión absoluta de saturación correspondiente a To y Tk (en mezclas zeotrópicas, en el punto de rocío).
A6: C3 | B6: Estado a la salida del evaporador y aspiración | C6: Ubica y lee los estados de vapor recalentado 1' y 1 con el recalentamiento útil y total.
A7: C4 | B7: Proceso de compresión | C7: Sigue la isentrópica hasta Pk y, si aplica, corrige con el rendimiento isentrópico; lee h2 y T2.
A8: C5 | B8: Condensación y subenfriamiento | C8: Ubica el líquido subenfriado a la salida del condensador y lee h3.
A9: C6 | B9: Expansión isoentálpica | C9: Reconoce que la expansión mantiene la entalpía (punto 4 en la vertical de 3).
A10: C7 | B10: Balance de energía y COP | C10: Calcula efecto frigorífico, trabajo de compresión y COP a partir de entalpías.
A11: C8 | B11: Dimensionamiento (caudal y potencias) | C11: Calcula caudal másico y potencias con unidades consistentes.
A14: Ítem | B14: Tipo de ítem | C14: Niveles donde aparece | D14: C1 | E14: C2 | F14: C3 | G14: C4 | H14: C5 | I14: C6 | J14: C7 | K14: C8
A15: Punto 1' | B15: Colocación en diagrama | C15: 2 y 3 | D15: 0 | E15: 0 | F15: 1 | G15: 0 | H15: 0 | I15: 0 | J15: 0 | K15: 0
A16: Punto 1 | B16: Colocación en diagrama | C16: 1, 2 y 3 | D16: 0 | E16: 0 | F16: 1 | G16: 0 | H16: 0 | I16: 0 | J16: 0 | K16: 0
A17: Punto 2 | B17: Colocación en diagrama | C17: 1, 2 y 3 | D17: 0 | E17: 0 | F17: 0 | G17: 1 | H17: 0 | I17: 0 | J17: 0 | K17: 0
A18: Punto 3 | B18: Colocación en diagrama | C18: 1, 2 y 3 | D18: 0 | E18: 0 | F18: 0 | G18: 0 | H18: 1 | I18: 0 | J18: 0 | K18: 0
A19: Punto 4 | B19: Colocación en diagrama | C19: 1, 2 y 3 | D19: 0 | E19: 0 | F19: 0 | G19: 0 | H19: 0 | I19: 1 | J19: 0 | K19: 0
A20: To | B20: Cálculo | C20: 2 y 3 | D20: 1 | E20: 0 | F20: 0 | G20: 0 | H20: 0 | I20: 0 | J20: 0 | K20: 0
A21: Tk | B21: Cálculo | C21: 2 y 3 | D21: 1 | E21: 0 | F21: 0 | G21: 0 | H21: 0 | I21: 0 | J21: 0 | K21: 0
A22: Po | B22: Lectura del diagrama | C22: 1, 2 y 3 | D22: 0 | E22: 1 | F22: 0 | G22: 0 | H22: 0 | I22: 0 | J22: 0 | K22: 0
A23: Pk | B23: Lectura del diagrama | C23: 1, 2 y 3 | D23: 0 | E23: 1 | F23: 0 | G23: 0 | H23: 0 | I23: 0 | J23: 0 | K23: 0
A24: h1u | B24: Lectura del diagrama | C24: 2 y 3 | D24: 0 | E24: 0 | F24: 1 | G24: 0 | H24: 0 | I24: 0 | J24: 0 | K24: 0
A25: h1 | B25: Lectura del diagrama | C25: 1, 2 y 3 | D25: 0 | E25: 0 | F25: 1 | G25: 0 | H25: 0 | I25: 0 | J25: 0 | K25: 0
A26: h2 | B26: Lectura del diagrama | C26: 1, 2 y 3 | D26: 0 | E26: 0 | F26: 0 | G26: 1 | H26: 0 | I26: 0 | J26: 0 | K26: 0
... A34: Qk | B34: Cálculo | C34: 3 | D34: 0 | E34: 0 | F34: 0 | G34: 0 | H34: 0 | I34: 0 | J34: 0 | K34: 1

Sheet Catalogo_errores
A1: Catálogo de errores tipificados
A2: La aplicación asigna el código comparando la respuesta con los valores que produciría cada concepción errónea. Si no coincide con ninguna, usa LEC/CAL (error pequeño) u OTR.
A4: Código | B4: Descripción | C4: Tipo | D4: Ítems donde se detecta | E4: Intervención didáctica sugerida
A5: LEC | B5: Lectura imprecisa del diagrama | C5: Precisión de lectura | D5: Lecturas y colocación | E5: Práctica de interpolación en escala logarítmica de presión y en la retícula de entalpía.
A6: CAL | B6: Cálculo impreciso | C6: Precisión aritmética | D6: Cálculos | E6: Revisar cifras significativas y redondeos intermedios.
A7: ARR | B7: Error arrastrado (procedimiento correcto con datos propios erróneos) | C7: Arrastre | D7: Po, Pk, h2, qom, w, COP, mh, Wc, Qk, Punto 4 | E7: No es un error del procedimiento: atender el dato previo que lo originó.
A8: SR | B8: Sin respuesta | C8: Omisión | D8: Todos | E8: Revisar tiempo disponible y claridad del enunciado.
A9: OTR | B9: Error no tipificado (más de 3 veces la tolerancia) | C9: No clasificado | D9: Todos | E9: Revisar individualmente; puede revelar una concepción no prevista.
A10: E01 | B10: Usa presión manométrica en lugar de absoluta | C10: Conceptual | D10: Po, Pk | E10: Contrastar lectura de manómetro con el eje del diagrama (presión absoluta).
A11: E02 | B11: Intercambia presión de alta y baja | C11: Conceptual | D11: Po, Pk, todos los puntos | E11: Relacionar cada componente con su lado de presión en el esquema del ciclo.
A12: E03 | B12: Error de signo al obtener To o Tk | C12: Conceptual | D12: To, Tk | E12: Explicar por qué el evaporador debe estar más frío que la cámara y el condensador más caliente que el ambiente.
A13: E04 | B13: Ignora el recalentamiento (toma vapor saturado) | C13: Conceptual | D13: Punto 1', Punto 1, h1u, h1 | E13: Ubicar isotermas en la zona de vapor recalentado; práctica con distintos recalentamientos.
A14: E05 | B14: Confunde recalentamiento útil con total | C14: Conceptual | D14: Punto 1, h1u, h1, w | E14: Distinguir el calor tomado dentro de la cámara del ganado en la línea de aspiración.
A15: E06 | B15: No aplica el rendimiento isentrópico | C15: Conceptual | D15: Punto 2, h2, T2 | E15: Comparar compresión ideal y real en el diagrama; efecto en T2 y en el consumo.
... A23: E14 | B23: Expansión no isoentálpica | C23: Conceptual | D23: Punto 4 | E23: Balance de energía en la válvula: sin calor ni trabajo, h constante.

Sheet Analisis_grupo
A1: Análisis del grupo
A2: Cambia los filtros amarillos. «Todos» incluye todos los valores. Los porcentajes se calculan sobre los ítems contestados y no contestados.
A4: Modo | B4: Evaluación | C4: =IF($B$4="Todos","<>",$B$4) -> Evaluación | D4: ← criterio usado por las fórmulas
A5: Grupo | B5: Todos | C5: =IF($B$5="Todos","<>",$B$5) -> <>
A6: Momento | B6: Todos | C6: =IF($B$6="Todos","<>",$B$6) -> <>
A7: Umbral de dominio (fracción) | B7: 0.7
A8: Calificación aprobatoria | B8: 7
A10: Indicadores generales
A11: Problemas registrados | B11: =COUNTIFS(Datos_problemas!$F:$F,$C$4,Datos_problemas!$D:$D,$C$5,Datos_problemas!$E:$E,$C$6) -> 0
A12: Estudiantes distintos (todos los datos) | B12: =MAX(Datos_problemas!$AV:$AV) -> 0
A13: Calificación promedio | B13: =IFERROR(AVERAGEIFS(Datos_problemas!$AE:$AE,Datos_problemas!$F:$F,$C$4,Datos_problemas!$D:$D,$C$5,Datos_problemas!$E:$E,$C$6),"")
A14: Problemas con calificación aprobatoria | B14: =IFERROR(COUNTIFS(Datos_problemas!$F:$F,$C$4,Datos_problemas!$D:$D,$C$5,Datos_problemas!$E:$E,$C$6,Datos_problemas!$AE:$AE,">="&$B$8)/B11,"")
A15: Tiempo promedio por problema (min) | B15: =IFERROR(AVERAGEIFS(Datos_problemas!$Y:$Y,Datos_problemas!$F:$F,$C$4,Datos_problemas!$D:$D,$C$5,Datos_problemas!$E:$E,$C$6)/60,"")
A16: Acierto en colocación de puntos | B16: =IFERROR(AVERAGEIFS(Datos_problemas!$AC:$AC,Datos_problemas!$F:$F,$C$4,Datos_problemas!$D:$D,$C$5,Datos_problemas!$E:$E,$C$6)/100,"")
A17: Acierto en lecturas y cálculos | B17: =IFERROR(AVERAGEIFS(Datos_problemas!$AD:$AD,Datos_problemas!$F:$F,$C$4,Datos_problemas!$D:$D,$C$5,Datos_problemas!$E:$E,$C$6)/100,"")
A18: Errores conceptuales por problema | B18: =IFERROR(AVERAGEIFS(Datos_problemas!$AJ:$AJ,Datos_problemas!$F:$F,$C$4,Datos_problemas!$D:$D,$C$5,Datos_problemas!$E:$E,$C$6),"")
A19: Errores arrastrados por problema | B19: =IFERROR(AVERAGEIFS(Datos_problemas!$AK:$AK,Datos_problemas!$F:$F,$C$4,Datos_problemas!$D:$D,$C$5,Datos_problemas!$E:$E,$C$6),"")
A21: A. Acierto por competencia y tipo de ítem
A22: Competencia | B22: Nombre | C22: Colocación en diagrama | D22: Lectura del diagrama | E22: Cálculo | F22: Total | G22: Ítems evaluados | H22: ¿Dominada?
A23: C1 | B23: Condiciones de operación (To, Tk) | C23: =IFERROR(SUMIFS(Datos_items!$Z:$Z,Datos_items!$O:$O,$A23,Datos_items!$N:$N,C$22,Datos_items!$E:$E,$C$4,Datos_items!$C:$C,$C$5,Datos_items!$D:$D,$C$6)/COUNTIFS(Datos_items!$O:$O,$A23,Datos_items!$N:$N,C$22,Datos_items!$E:$E,$C$4,Datos_items!$C:$C,$C$5,Datos_items!$D:$D,$C$6),"") | D23: =IFERROR(SUMIFS(Datos_items!$Z:$Z,Datos_items!$O:$O,$A23,Datos_items!$N:$N,D$22,Datos_items!$E:$E,$C$4,Datos_items!$C:$C,$C$5,Datos_items!$D:$D,$C$6)/COUNTIFS(Datos_items!$O:$O,$A23,Datos_items!$N:$N,D$22,Datos_items!$E:$E,$C$4,Datos_items!$C:$C,$C$5,Datos_items!$D:$D,$C$6),"") | E23: =IFERROR(SUMIFS(Datos_items!$Z:$Z,Datos_items!$O:$O,$A23,Datos_items!$N:$N,E$22,Datos_items!$E:$E,$C$4,Datos_items!$C:$C,$C$5,Datos_items!$D:$D,$C$6)/COUNTIFS(Datos_items!$O:$O,$A23,Datos_items!$N:$N,E$22,Datos_items!$E:$E,$C$4,Datos_items!$C:$C,$C$5,Datos_items!$D:$D,$C$6),"") | F23: =IFERROR(SUMIFS(Datos_items!$Z:$Z,Datos_items!$O:$O,$A23,Datos_items!$E:$E,$C$4,Datos_items!$C:$C,$C$5,Datos_items!$D:$D,$C$6)/COUNTIFS(Datos_items!$O:$O,$A23,Datos_items!$E:$E,$C$4,Datos_items!$C:$C,$C$5,Datos_items!$D:$D,$C$6),"") | G23: =COUNTIFS(Datos_items!$O:$O,$A23,Datos_items!$E:$E,$C$4,Datos_items!$C:$C,$C$5,Datos_items!$D:$D,$C$6) -> 0 | H23: =IF(F23="","",IF(F23>=$B$7,"Sí","No"))
A24: C2 | B24: Presiones de saturación | C24: =IFERROR(SUMIFS(Datos_items!$Z:$Z,Datos_items!$O:$O,$A24,Datos_items!$N:$N,C$22,Datos_items!$E:$E,$C$4,Datos_items!$C:$C,$C$5,Datos_items!$D:$D,$C$6)/COUNTIFS(Datos_items!$O:$O,$A24,Datos_items!$N:$N,C$22,Datos_items!$E:$E,$C$4,Datos_items!$C:$C,$C$5,Datos_items!$D:$D,$C$6),"") | D24: =IFERROR(SUMIFS(Datos_items!$Z:$Z,Datos_items!$O:$O,$A24,Datos_items!$N:$N,D$22,Datos_items!$E:$E,$C$4,Datos_items!$C:$C,$C$5,Datos_items!$D:$D,$C$6)/COUNTIFS(Datos_items!$O:$O,$A24,Datos_items!$N:$N,D$22,Datos_items!$E:$E,$C$4,Datos_items!$C:$C,$C$5,Datos_items!$D:$D,$C$6),"") | E24: =IFERROR(SUMIFS(Datos_items!$Z:$Z,Datos_items!$O:$O,$A24,Datos_items!$N:$N,E$22,Datos_items!$E:$E,$C$4,Datos_items!$C:$C,$C$5,Datos_items!$D:$D,$C$6)/COUNTIFS(Datos_items!$O:$O,$A24,Datos_items!$N:$N,E$22,Datos_items!$E:$E,$C$4,Datos_items!$C:$C,$C$5,Datos_items!$D:$D,$C$6),"") | F24: =IFERROR(SUMIFS(Datos_items!$Z:$Z,Datos_items!$O:$O,$A24,Datos_items!$E:$E,$C$4,Datos_items!$C:$C,$C$5,Datos_items!$D:$D,$C$6)/COUNTIFS(Datos_items!$O:$O,$A24,Datos_items!$E:$E,$C$4,Datos_items!$C:$C,$C$5,Datos_items!$D:$D,$C$6),"") | G24: =COUNTIFS(Datos_items!$O:$O,$A24,Datos_items!$E:$E,$C$4,Datos_items!$C:$C,$C$5,Datos_items!$D:$D,$C$6) -> 0 | H24: =IF(F24="","",IF(F24>=$B$7,"Sí","No"))
A25: C3 | B25: Estado a la salida del evaporador y aspiración | C25: =IFERROR(SUMIFS(Datos_items!$Z:$Z,Datos_items!$O:$O,$A25,Datos_items!$N:$N,C$22,Datos_items!$E:$E,$C$4,Datos_items!$C:$C,$C$5,Datos_items!$D:$D,$C$6)/COUNTIFS(Datos_items!$O:$O,$A25,Datos_items!$N:$N,C$22,Datos_items!$E:$E,$C$4,Datos_items!$C:$C,$C$5,Datos_items!$D:$D,$C$6),"") | D25: =IFERROR(SUMIFS(Datos_items!$Z:$Z,Datos_items!$O:$O,$A25,Datos_items!$N:$N,D$22,Datos_items!$E:$E,$C$4,Datos_items!$C:$C,$C$5,Datos_items!$D:$D,$C$6)/COUNTIFS(Datos_items!$O:$O,$A25,Datos_items!$N:$N,D$22,Datos_items!$E:$E,$C$4,Datos_items!$C:$C,$C$5,Datos_items!$D:$D,$C$6),"") | E25: =IFERROR(SUMIFS(Datos_items!$Z:$Z,Datos_items!$O:$O,$A25,Datos_items!$N:$N,E$22,Datos_items!$E:$E,$C$4,Datos_items!$C:$C,$C$5,Datos_items!$D:$D,$C$6)/COUNTIFS(Datos_items!$O:$O,$A25,Datos_items!$N:$N,E$22,Datos_items!$E:$E,$C$4,Datos_items!$C:$C,$C$5,Datos_items!$D:$D,$C$6),"") | F25: =IFERROR(SUMIFS(Datos_items!$Z:$Z,Datos_items!$O:$O,$A25,Datos_items!$E:$E,$C$4,Datos_items!$C:$C,$C$5,Datos_items!$D:$D,$C$6)/COUNTIFS(Datos_items!$O:$O,$A25,Datos_items!$E:$E,$C$4,Datos_items!$C:$C,$C$5,Datos_items!$D:$D,$C$6),"") | G25: =COUNTIFS(Datos_items!$O:$O,$A25,Datos_items!$E:$E,$C$4,Datos_items!$C:$C,$C$5,Datos_items!$D:$D,$C$6) -> 0 | H25: =IF(F25="","",IF(F25>=$B$7,"Sí","No"))
A26: C4 | B26: Proceso de compresión | C26: =IFERROR(SUMIFS(Datos_items!$Z:$Z,Datos_items!$O:$O,$A26,Datos_items!$N:$N,C$22,Datos_items!$E:$E,$C$4,Datos_items!$C:$C,$C$5,Datos_items!$D:$D,$C$6)/COUNTIFS(Datos_items!$O:$O,$A26,Datos_items!$N:$N,C$22,Datos_items!$E:$E,$C$4,Datos_items!$C:$C,$C$5,Datos_items!$D:$D,$C$6),"") | D26: =IFERROR(SUMIFS(Datos_items!$Z:$Z,Datos_items!$O:$O,$A26,Datos_items!$N:$N,D$22,Datos_items!$E:$E,$C$4,Datos_items!$C:$C,$C$5,Datos_items!$D:$D,$C$6)/COUNTIFS(Datos_items!$O:$O,$A26,Datos_items!$N:$N,D$22,Datos_items!$E:$E,$C$4,Datos_items!$C:$C,$C$5,Datos_items!$D:$D,$C$6),"") | E26: =IFERROR(SUMIFS(Datos_items!$Z:$Z,Datos_items!$O:$O,$A26,Datos_items!$N:$N,E$22,Datos_items!$E:$E,$C$4,Datos_items!$C:$C,$C$5,Datos_items!$D:$D,$C$6)/COUNTIFS(Datos_items!$O:$O,$A26,Datos_items!$N:$N,E$22,Datos_items!$E:$E,$C$4,Datos_items!$C:$C,$C$5,Datos_items!$D:$D,$C$6),"") | F26: =IFERROR(SUMIFS(Datos_items!$Z:$Z,Datos_items!$O:$O,$A26,Datos_items!$E:$E,$C$4,Datos_items!$C:$C,$C$5,Datos_items!$D:$D,$C$6)/COUNTIFS(Datos_items!$O:$O,$A26,Datos_items!$E:$E,$C$4,Datos_items!$C:$C,$C$5,Datos_items!$D:$D,$C$6),"") | G26: =COUNTIFS(Datos_items!$O:$O,$A26,Datos_items!$E:$E,$C$4,Datos_items!$C:$C,$C$5,Datos_items!$D:$D,$C$6) -> 0 | H26: =IF(F26="","",IF(F26>=$B$7,"Sí","No"))
A27: C5 | B27: Condensación y subenfriamiento | C27: =IFERROR(SUMIFS(Datos_items!$Z:$Z,Datos_items!$O:$O,$A27,Datos_items!$N:$N,C$22,Datos_items!$E:$E,$C$4,Datos_items!$C:$C,$C$5,Datos_items!$D:$D,$C$6)/COUNTIFS(Datos_items!$O:$O,$A27,Datos_items!$N:$N,C$22,Datos_items!$E:$E,$C$4,Datos_items!$C:$C,$C$5,Datos_items!$D:$D,$C$6),"") | D27: =IFERROR(SUMIFS(Datos_items!$Z:$Z,Datos_items!$O:$O,$A27,Datos_items!$N:$N,D$22,Datos_items!$E:$E,$C$4,Datos_items!$C:$C,$C$5,Datos_items!$D:$D,$C$6)/COUNTIFS(Datos_items!$O:$O,$A27,Datos_items!$N:$N,D$22,Datos_items!$E:$E,$C$4,Datos_items!$C:$C,$C$5,Datos_items!$D:$D,$C$6),"") | E27: =IFERROR(SUMIFS(Datos_items!$Z:$Z,Datos_items!$O:$O,$A27,Datos_items!$N:$N,E$22,Datos_items!$E:$E,$C$4,Datos_items!$C:$C,$C$5,Datos_items!$D:$D,$C$6)/COUNTIFS(Datos_items!$O:$O,$A27,Datos_items!$N:$N,E$22,Datos_items!$E:$E,$C$4,Datos_items!$C:$C,$C$5,Datos_items!$D:$D,$C$6),"") | F27: =IFERROR(SUMIFS(Datos_items!$Z:$Z,Datos_items!$O:$O,$A27,Datos_items!$E:$E,$C$4,Datos_items!$C:$C,$C$5,Datos_items!$D:$D,$C$6)/COUNTIFS(Datos_items!$O:$O,$A27,Datos_items!$E:$E,$C$4,Datos_items!$C:$C,$C$5,Datos_items!$D:$D,$C$6),"") | G27: =COUNTIFS(Datos_items!$O:$O,$A27,Datos_items!$E:$E,$C$4,Datos_items!$C:$C,$C$5,Datos_items!$D:$D,$C$6) -> 0 | H27: =IF(F27="","",IF(F27>=$B$7,"Sí","No"))
A28: C6 | B28: Expansión isoentálpica | C28: =IFERROR(SUMIFS(Datos_items!$Z:$Z,Datos_items!$O:$O,$A28,Datos_items!$N:$N,C$22,Datos_items!$E:$E,$C$4,Datos_items!$C:$C,$C$5,Datos_items!$D:$D,$C$6)/COUNTIFS(Datos_items!$O:$O,$A28,Datos_items!$N:$N,C$22,Datos_items!$E:$E,$C$4,Datos_items!$C:$C,$C$5,Datos_items!$D:$D,$C$6),"") | D28: =IFERROR(SUMIFS(Datos_items!$Z:$Z,Datos_items!$O:$O,$A28,Datos_items!$N:$N,D$22,Datos_items!$E:$E,$C$4,Datos_items!$C:$C,$C$5,Datos_items!$D:$D,$C$6)/COUNTIFS(Datos_items!$O:$O,$A28,Datos_items!$N:$N,D$22,Datos_items!$E:$E,$C$4,Datos_items!$C:$C,$C$5,Datos_items!$D:$D,$C$6),"") | E28: =IFERROR(SUMIFS(Datos_items!$Z:$Z,Datos_items!$O:$O,$A28,Datos_items!$N:$N,E$22,Datos_items!$E:$E,$C$4,Datos_items!$C:$C,$C$5,Datos_items!$D:$D,$C$6)/COUNTIFS(Datos_items!$O:$O,$A28,Datos_items!$N:$N,E$22,Datos_items!$E:$E,$C$4,Datos_items!$C:$C,$C$5,Datos_items!$D:$D,$C$6),"") | F28: =IFERROR(SUMIFS(Datos_items!$Z:$Z,Datos_items!$O:$O,$A28,Datos_items!$E:$E,$C$4,Datos_items!$C:$C,$C$5,Datos_items!$D:$D,$C$6)/COUNTIFS(Datos_items!$O:$O,$A28,Datos_items!$E:$E,$C$4,Datos_items!$C:$C,$C$5,Datos_items!$D:$D,$C$6),"") | G28: =COUNTIFS(Datos_items!$O:$O,$A28,Datos_items!$E:$E,$C$4,Datos_items!$C:$C,$C$5,Datos_items!$D:$D,$C$6) -> 0 | H28: =IF(F28="","",IF(F28>=$B$7,"Sí","No"))
A29: C7 | B29: Balance de energía y COP | C29: =IFERROR(SUMIFS(Datos_items!$Z:$Z,Datos_items!$O:$O,$A29,Datos_items!$N:$N,C$22,Datos_items!$E:$E,$C$4,Datos_items!$C:$C,$C$5,Datos_items!$D:$D,$C$6)/COUNTIFS(Datos_items!$O:$O,$A29,Datos_items!$N:$N,C$22,Datos_items!$E:$E,$C$4,Datos_items!$C:$C,$C$5,Datos_items!$D:$D,$C$6),"") | D29: =IFERROR(SUMIFS(Datos_items!$Z:$Z,Datos_items!$O:$O,$A29,Datos_items!$N:$N,D$22,Datos_items!$E:$E,$C$4,Datos_items!$C:$C,$C$5,Datos_items!$D:$D,$C$6)/COUNTIFS(Datos_items!$O:$O,$A29,Datos_items!$N:$N,D$22,Datos_items!$E:$E,$C$4,Datos_items!$C:$C,$C$5,Datos_items!$D:$D,$C$6),"") | E29: =IFERROR(SUMIFS(Datos_items!$Z:$Z,Datos_items!$O:$O,$A29,Datos_items!$N:$N,E$22,Datos_items!$E:$E,$C$4,Datos_items!$C:$C,$C$5,Datos_items!$D:$D,$C$6)/COUNTIFS(Datos_items!$O:$O,$A29,Datos_items!$N:$N,E$22,Datos_items!$E:$E,$C$4,Datos_items!$C:$C,$C$5,Datos_items!$D:$D,$C$6),"") | F29: =IFERROR(SUMIFS(Datos_items!$Z:$Z,Datos_items!$O:$O,$A29,Datos_items!$E:$E,$C$4,Datos_items!$C:$C,$C$5,Datos_items!$D:$D,$C$6)/COUNTIFS(Datos_items!$O:$O,$A29,Datos_items!$E:$E,$C$4,Datos_items!$C:$C,$C$5,Datos_items!$D:$D,$C$6),"") | G29: =COUNTIFS(Datos_items!$O:$O,$A29,Datos_items!$E:$E,$C$4,Datos_items!$C:$C,$C$5,Datos_items!$D:$D,$C$6) -> 0 | H29: =IF(F29="","",IF(F29>=$B$7,"Sí","No"))
A30: C8 | B30: Dimensionamiento (caudal y potencias) | C30: =IFERROR(SUMIFS(Datos_items!$Z:$Z,Datos_items!$O:$O,$A30,Datos_items!$N:$N,C$22,Datos_items!$E:$E,$C$4,Datos_items!$C:$C,$C$5,Datos_items!$D:$D,$C$6)/COUNTIFS(Datos_items!$O:$O,$A30,Datos_items!$N:$N,C$22,Datos_items!$E:$E,$C$4,Datos_items!$C:$C,$C$5,Datos_items!$D:$D,$C$6),"") | D30: =IFERROR(SUMIFS(Datos_items!$Z:$Z,Datos_items!$O:$O,$A30,Datos_items!$N:$N,D$22,Datos_items!$E:$E,$C$4,Datos_items!$C:$C,$C$5,Datos_items!$D:$D,$C$6)/COUNTIFS(Datos_items!$O:$O,$A30,Datos_items!$N:$N,D$22,Datos_items!$E:$E,$C$4,Datos_items!$C:$C,$C$5,Datos_items!$D:$D,$C$6),"") | E30: =IFERROR(SUMIFS(Datos_items!$Z:$Z,Datos_items!$O:$O,$A30,Datos_items!$N:$N,E$22,Datos_items!$E:$E,$C$4,Datos_items!$C:$C,$C$5,Datos_items!$D:$D,$C$6)/COUNTIFS(Datos_items!$O:$O,$A30,Datos_items!$N:$N,E$22,Datos_items!$E:$E,$C$4,Datos_items!$C:$C,$C$5,Datos_items!$D:$D,$C$6),"") | F30: =IFERROR(SUMIFS(Datos_items!$Z:$Z,Datos_items!$O:$O,$A30,Datos_items!$E:$E,$C$4,Datos_items!$C:$C,$C$5,Datos_items!$D:$D,$C$6)/COUNTIFS(Datos_items!$O:$O,$A30,Datos_items!$E:$E,$C$4,Datos_items!$C:$C,$C$5,Datos_items!$D:$D,$C$6),"") | G30: =COUNTIFS(Datos_items!$O:$O,$A30,Datos_items!$E:$E,$C$4,Datos_items!$C:$C,$C$5,Datos_items!$D:$D,$C$6) -> 0 | H30: =IF(F30="","",IF(F30>=$B$7,"Sí","No"))
A32: B. Acierto por ítem y mapa de errores (número de veces que ocurrió cada código)
A33: Ítem | B33: Competencia | C33: Respuestas | D33: Acierto | E33: Error más frecuente | F33: LEC | G33: CAL | H33: ARR | I33: SR | J33: OTR | K33: E01 | L33: E02 | M33: E03 | N33: E04 | O33: E05 | P33: E06 | Q33: E07 | R33: E08 | S33: E09 | T33: E10 | U33: E11 | V33: E12 | W33: E13 | X33: E14
A34: Punto 1' | B34: C3 | C34: =COUNTIFS(Datos_items!$L:$L,$A34,Datos_items!$E:$E,$C$4,Datos_items!$C:$C,$C$5,Datos_items!$D:$D,$C$6) -> 0 | D34: =IFERROR(SUMIFS(Datos_items!$Z:$Z,Datos_items!$L:$L,$A34,Datos_items!$E:$E,$C$4,Datos_items!$C:$C,$C$5,Datos_items!$D:$D,$C$6)/C34,"") | E34: =IF(MAX(F34:X34)=0,"",INDEX($F$33:$X$33,MATCH(MAX(F34:X34),F34:X34,0))) | F34: =COUNTIFS(Datos_items!$L:$L,$A34,Datos_items!$AA:$AA,F$33,Datos_items!$E:$E,$C$4,Datos_items!$C:$C,$C$5,Datos_items!$D:$D,$C$6) -> 0 | G34: =COUNTIFS(Datos_items!$L:$L,$A34,Datos_items!$AA:$AA,G$33,Datos_items!$E:$E,$C$4,Datos_items!$C:$C,$C$5,Datos_items!$D:$D,$C$6) -> 0 | H34: =COUNTIFS(Datos_items!$L:$L,$A34,Datos_items!$AA:$AA,H$33,Datos_items!$E:$E,$C$4,Datos_items!$C:$C,$C$5,Datos_items!$D:$D,$C$6) -> 0 | I34: =COUNTIFS(Datos_items!$L:$L,$A34,Datos_items!$AA:$AA,I$33,Datos_items!$E:$E,$C$4,Datos_items!$C:$C,$C$5,Datos_items!$D:$D,$C$6) -> 0 | J34: =COUNTIFS(Datos_items!$L:$L,$A34,Datos_items!$AA:$AA,J$33,Datos_items!$E:$E,$C$4,Datos_items!$C:$C,$C$5,Datos_items!$D:$D,$C$6) -> 0 | K34: =COUNTIFS(Datos_items!$L:$L,$A34,Datos_items!$AA:$AA,K$33,Datos_items!$E:$E,$C$4,Datos_items!$C:$C,$C$5,Datos_items!$D:$D,$C$6) -> 0 | L34: =COUNTIFS(Datos_items!$L:$L,$A34,Datos_items!$AA:$AA,L$33,Datos_items!$E:$E,$C$4,Datos_items!$C:$C,$C$5,Datos_items!$D:$D,$C$6) -> 0 | M34: =COUNTIFS(Datos_items!$L:$L,$A34,Datos_items!$AA:$AA,M$33,Datos_items!$E:$E,$C$4,Datos_items!$C:$C,$C$5,Datos_items!$D:$D,$C$6) -> 0 | ... X34: =COUNTIFS(Datos_items!$L:$L,$A34,Datos_items!$AA:$AA,X$33,Datos_items!$E:$E,$C$4,Datos_items!$C:$C,$C$5,Datos_items!$D:$D,$C$6) -> 0
A35: Punto 1 | B35: C3 | C35: =COUNTIFS(Datos_items!$L:$L,$A35,Datos_items!$E:$E,$C$4,Datos_items!$C:$C,$C$5,Datos_items!$D:$D,$C$6) -> 0 | D35: =IFERROR(SUMIFS(Datos_items!$Z:$Z,Datos_items!$L:$L,$A35,Datos_items!$E:$E,$C$4,Datos_items!$C:$C,$C$5,Datos_items!$D:$D,$C$6)/C35,"") | E35: =IF(MAX(F35:X35)=0,"",INDEX($F$33:$X$33,MATCH(MAX(F35:X35),F35:X35,0))) | F35: =COUNTIFS(Datos_items!$L:$L,$A35,Datos_items!$AA:$AA,F$33,Datos_items!$E:$E,$C$4,Datos_items!$C:$C,$C$5,Datos_items!$D:$D,$C$6) -> 0 | G35: =COUNTIFS(Datos_items!$L:$L,$A35,Datos_items!$AA:$AA,G$33,Datos_items!$E:$E,$C$4,Datos_items!$C:$C,$C$5,Datos_items!$D:$D,$C$6) -> 0 | H35: =COUNTIFS(Datos_items!$L:$L,$A35,Datos_items!$AA:$AA,H$33,Datos_items!$E:$E,$C$4,Datos_items!$C:$C,$C$5,Datos_items!$D:$D,$C$6) -> 0 | I35: =COUNTIFS(Datos_items!$L:$L,$A35,Datos_items!$AA:$AA,I$33,Datos_items!$E:$E,$C$4,Datos_items!$C:$C,$C$5,Datos_items!$D:$D,$C$6) -> 0 | J35: =COUNTIFS(Datos_items!$L:$L,$A35,Datos_items!$AA:$AA,J$33,Datos_items!$E:$E,$C$4,Datos_items!$C:$C,$C$5,Datos_items!$D:$D,$C$6) -> 0 | K35: =COUNTIFS(Datos_items!$L:$L,$A35,Datos_items!$AA:$AA,K$33,Datos_items!$E:$E,$C$4,Datos_items!$C:$C,$C$5,Datos_items!$D:$D,$C$6) -> 0 | L35: =COUNTIFS(Datos_items!$L:$L,$A35,Datos_items!$AA:$AA,L$33,Datos_items!$E:$E,$C$4,Datos_items!$C:$C,$C$5,Datos_items!$D:$D,$C$6) -> 0 | M35: =COUNTIFS(Datos_items!$L:$L,$A35,Datos_items!$AA:$AA,M$33,Datos_items!$E:$E,$C$4,Datos_items!$C:$C,$C$5,Datos_items!$D:$D,$C$6) -> 0 | ... X35: =COUNTIFS(Datos_items!$L:$L,$A35,Datos_items!$AA:$AA,X$33,Datos_items!$E:$E,$C$4,Datos_items!$C:$C,$C$5,Datos_items!$D:$D,$C$6) -> 0
A36: Punto 2 | B36: C4 | C36: =COUNTIFS(Datos_items!$L:$L,$A36,Datos_items!$E:$E,$C$4,Datos_items!$C:$C,$C$5,Datos_items!$D:$D,$C$6) -> 0 | D36: =IFERROR(SUMIFS(Datos_items!$Z:$Z,Datos_items!$L:$L,$A36,Datos_items!$E:$E,$C$4,Datos_items!$C:$C,$C$5,Datos_items!$D:$D,$C$6)/C36,"") | E36: =IF(MAX(F36:X36)=0,"",INDEX($F$33:$X$33,MATCH(MAX(F36:X36),F36:X36,0))) | F36: =COUNTIFS(Datos_items!$L:$L,$A36,Datos_items!$AA:$AA,F$33,Datos_items!$E:$E,$C$4,Datos_items!$C:$C,$C$5,Datos_items!$D:$D,$C$6) -> 0 | G36: =COUNTIFS(Datos_items!$L:$L,$A36,Datos_items!$AA:$AA,G$33,Datos_items!$E:$E,$C$4,Datos_items!$C:$C,$C$5,Datos_items!$D:$D,$C$6) -> 0 | H36: =COUNTIFS(Datos_items!$L:$L,$A36,Datos_items!$AA:$AA,H$33,Datos_items!$E:$E,$C$4,Datos_items!$C:$C,$C$5,Datos_items!$D:$D,$C$6) -> 0 | I36: =COUNTIFS(Datos_items!$L:$L,$A36,Datos_items!$AA:$AA,I$33,Datos_items!$E:$E,$C$4,Datos_items!$C:$C,$C$5,Datos_items!$D:$D,$C$6) -> 0 | J36: =COUNTIFS(Datos_items!$L:$L,$A36,Datos_items!$AA:$AA,J$33,Datos_items!$E:$E,$C$4,Datos_items!$C:$C,$C$5,Datos_items!$D:$D,$C$6) -> 0 | K36: =COUNTIFS(Datos_items!$L:$L,$A36,Datos_items!$AA:$AA,K$33,Datos_items!$E:$E,$C$4,Datos_items!$C:$C,$C$5,Datos_items!$D:$D,$C$6) -> 0 | L36: =COUNTIFS(Datos_items!$L:$L,$A36,Datos_items!$AA:$AA,L$33,Datos_items!$E:$E,$C$4,Datos_items!$C:$C,$C$5,Datos_items!$D:$D,$C$6) -> 0 | M36: =COUNTIFS(Datos_items!$L:$L,$A36,Datos_items!$AA:$AA,M$33,Datos_items!$E:$E,$C$4,Datos_items!$C:$C,$C$5,Datos_items!$D:$D,$C$6) -> 0 | ... X36: =COUNTIFS(Datos_items!$L:$L,$A36,Datos_items!$AA:$AA,X$33,Datos_items!$E:$E,$C$4,Datos_items!$C:$C,$C$5,Datos_items!$D:$D,$C$6) -> 0
A37: Punto 3 | B37: C5 | C37: =COUNTIFS(Datos_items!$L:$L,$A37,Datos_items!$E:$E,$C$4,Datos_items!$C:$C,$C$5,Datos_items!$D:$D,$C$6) -> 0 | D37: =IFERROR(SUMIFS(Datos_items!$Z:$Z,Datos_items!$L:$L,$A37,Datos_items!$E:$E,$C$4,Datos_items!$C:$C,$C$5,Datos_items!$D:$D,$C$6)/C37,"") | E37: =IF(MAX(F37:X37)=0,"",INDEX($F$33:$X$33,MATCH(MAX(F37:X37),F37:X37,0))) | F37: =COUNTIFS(Datos_items!$L:$L,$A37,Datos_items!$AA:$AA,F$33,Datos_items!$E:$E,$C$4,Datos_items!$C:$C,$C$5,Datos_items!$D:$D,$C$6) -> 0 | G37: =COUNTIFS(Datos_items!$L:$L,$A37,Datos_items!$AA:$AA,G$33,Datos_items!$E:$E,$C$4,Datos_items!$C:$C,$C$5,Datos_items!$D:$D,$C$6) -> 0 | H37: =COUNTIFS(Datos_items!$L:$L,$A37,Datos_items!$AA:$AA,H$33,Datos_items!$E:$E,$C$4,Datos_items!$C:$C,$C$5,Datos_items!$D:$D,$C$6) -> 0 | I37: =COUNTIFS(Datos_items!$L:$L,$A37,Datos_items!$AA:$AA,I$33,Datos_items!$E:$E,$C$4,Datos_items!$C:$C,$C$5,Datos_items!$D:$D,$C$6) -> 0 | J37: =COUNTIFS(Datos_items!$L:$L,$A37,Datos_items!$AA:$AA,J$33,Datos_items!$E:$E,$C$4,Datos_items!$C:$C,$C$5,Datos_items!$D:$D,$C$6) -> 0 | K37: =COUNTIFS(Datos_items!$L:$L,$A37,Datos_items!$AA:$AA,K$33,Datos_items!$E:$E,$C$4,Datos_items!$C:$C,$C$5,Datos_items!$D:$D,$C$6) -> 0 | L37: =COUNTIFS(Datos_items!$L:$L,$A37,Datos_items!$AA:$AA,L$33,Datos_items!$E:$E,$C$4,Datos_items!$C:$C,$C$5,Datos_items!$D:$D,$C$6) -> 0 | M37: =COUNTIFS(Datos_items!$L:$L,$A37,Datos_items!$AA:$AA,M$33,Datos_items!$E:$E,$C$4,Datos_items!$C:$C,$C$5,Datos_items!$D:$D,$C$6) -> 0 | ... X37: =COUNTIFS(Datos_items!$L:$L,$A37,Datos_items!$AA:$AA,X$33,Datos_items!$E:$E,$C$4,Datos_items!$C:$C,$C$5,Datos_items!$D:$D,$C$6) -> 0
A38: Punto 4 | B38: C6 | C38: =COUNTIFS(Datos_items!$L:$L,$A38,Datos_items!$E:$E,$C$4,Datos_items!$C:$C,$C$5,Datos_items!$D:$D,$C$6) -> 0 | D38: =IFERROR(SUMIFS(Datos_items!$Z:$Z,Datos_items!$L:$L,$A38,Datos_items!$E:$E,$C$4,Datos_items!$C:$C,$C$5,Datos_items!$D:$D,$C$6)/C38,"") | E38: =IF(MAX(F38:X38)=0,"",INDEX($F$33:$X$33,MATCH(MAX(F38:X38),F38:X38,0))) | F38: =COUNTIFS(Datos_items!$L:$L,$A38,Datos_items!$AA:$AA,F$33,Datos_items!$E:$E,$C$4,Datos_items!$C:$C,$C$5,Datos_items!$D:$D,$C$6) -> 0 | G38: =COUNTIFS(Datos_items!$L:$L,$A38,Datos_items!$AA:$AA,G$33,Datos_items!$E:$E,$C$4,Datos_items!$C:$C,$C$5,Datos_items!$D:$D,$C$6) -> 0 | H38: =COUNTIFS(Datos_items!$L:$L,$A38,Datos_items!$AA:$AA,H$33,Datos_items!$E:$E,$C$4,Datos_items!$C:$C,$C$5,Datos_items!$D:$D,$C$6) -> 0 | I38: =COUNTIFS(Datos_items!$L:$L,$A38,Datos_items!$AA:$AA,I$33,Datos_items!$E:$E,$C$4,Datos_items!$C:$C,$C$5,Datos_items!$D:$D,$C$6) -> 0 | J38: =COUNTIFS(Datos_items!$L:$L,$A38,Datos_items!$AA:$AA,J$33,Datos_items!$E:$E,$C$4,Datos_items!$C:$C,$C$5,Datos_items!$D:$D,$C$6) -> 0 | K38: =COUNTIFS(Datos_items!$L:$L,$A38,Datos_items!$AA:$AA,K$33,Datos_items!$E:$E,$C$4,Datos_items!$C:$C,$C$5,Datos_items!$D:$D,$C$6) -> 0 | L38: =COUNTIFS(Datos_items!$L:$L,$A38,Datos_items!$AA:$AA,L$33,Datos_items!$E:$E,$C$4,Datos_items!$C:$C,$C$5,Datos_items!$D:$D,$C$6) -> 0 | M38: =COUNTIFS(Datos_items!$L:$L,$A38,Datos_items!$AA:$AA,M$33,Datos_items!$E:$E,$C$4,Datos_items!$C:$C,$C$5,Datos_items!$D:$D,$C$6) -> 0 | ... X38: =COUNTIFS(Datos_items!$L:$L,$A38,Datos_items!$AA:$AA,X$33,Datos_items!$E:$E,$C$4,Datos_items!$C:$C,$C$5,Datos_items!$D:$D,$C$6) -> 0
A39: To | B39: C1 | C39: =COUNTIFS(Datos_items!$L:$L,$A39,Datos_items!$E:$E,$C$4,Datos_items!$C:$C,$C$5,Datos_items!$D:$D,$C$6) -> 0 | D39: =IFERROR(SUMIFS(Datos_items!$Z:$Z,Datos_items!$L:$L,$A39,Datos_items!$E:$E,$C$4,Datos_items!$C:$C,$C$5,Datos_items!$D:$D,$C$6)/C39,"") | E39: =IF(MAX(F39:X39)=0,"",INDEX($F$33:$X$33,MATCH(MAX(F39:X39),F39:X39,0))) | F39: =COUNTIFS(Datos_items!$L:$L,$A39,Datos_items!$AA:$AA,F$33,Datos_items!$E:$E,$C$4,Datos_items!$C:$C,$C$5,Datos_items!$D:$D,$C$6) -> 0 | G39: =COUNTIFS(Datos_items!$L:$L,$A39,Datos_items!$AA:$AA,G$33,Datos_items!$E:$E,$C$4,Datos_items!$C:$C,$C$5,Datos_items!$D:$D,$C$6) -> 0 | H39: =COUNTIFS(Datos_items!$L:$L,$A39,Datos_items!$AA:$AA,H$33,Datos_items!$E:$E,$C$4,Datos_items!$C:$C,$C$5,Datos_items!$D:$D,$C$6) -> 0 | I39: =COUNTIFS(Datos_items!$L:$L,$A39,Datos_items!$AA:$AA,I$33,Datos_items!$E:$E,$C$4,Datos_items!$C:$C,$C$5,Datos_items!$D:$D,$C$6) -> 0 | J39: =COUNTIFS(Datos_items!$L:$L,$A39,Datos_items!$AA:$AA,J$33,Datos_items!$E:$E,$C$4,Datos_items!$C:$C,$C$5,Datos_items!$D:$D,$C$6) -> 0 | K39: =COUNTIFS(Datos_items!$L:$L,$A39,Datos_items!$AA:$AA,K$33,Datos_items!$E:$E,$C$4,Datos_items!$C:$C,$C$5,Datos_items!$D:$D,$C$6) -> 0 | L39: =COUNTIFS(Datos_items!$L:$L,$A39,Datos_items!$AA:$AA,L$33,Datos_items!$E:$E,$C$4,Datos_items!$C:$C,$C$5,Datos_items!$D:$D,$C$6) -> 0 | M39: =COUNTIFS(Datos_items!$L:$L,$A39,Datos_items!$AA:$AA,M$33,Datos_items!$E:$E,$C$4,Datos_items!$C:$C,$C$5,Datos_items!$D:$D,$C$6) -> 0 | ... X39: =COUNTIFS(Datos_items!$L:$L,$A39,Datos_items!$AA:$AA,X$33,Datos_items!$E:$E,$C$4,Datos_items!$C:$C,$C$5,Datos_items!$D:$D,$C$6) -> 0
A40: Tk | B40: C1 | C40: =COUNTIFS(Datos_items!$L:$L,$A40,Datos_items!$E:$E,$C$4,Datos_items!$C:$C,$C$5,Datos_items!$D:$D,$C$6) -> 0 | D40: =IFERROR(SUMIFS(Datos_items!$Z:$Z,Datos_items!$L:$L,$A40,Datos_items!$E:$E,$C$4,Datos_items!$C:$C,$C$5,Datos_items!$D:$D,$C$6)/C40,"") | E40: =IF(MAX(F40:X40)=0,"",INDEX($F$33:$X$33,MATCH(MAX(F40:X40),F40:X40,0))) | F40: =COUNTIFS(Datos_items!$L:$L,$A40,Datos_items!$AA:$AA,F$33,Datos_items!$E:$E,$C$4,Datos_items!$C:$C,$C$5,Datos_items!$D:$D,$C$6) -> 0 | G40: =COUNTIFS(Datos_items!$L:$L,$A40,Datos_items!$AA:$AA,G$33,Datos_items!$E:$E,$C$4,Datos_items!$C:$C,$C$5,Datos_items!$D:$D,$C$6) -> 0 | H40: =COUNTIFS(Datos_items!$L:$L,$A40,Datos_items!$AA:$AA,H$33,Datos_items!$E:$E,$C$4,Datos_items!$C:$C,$C$5,Datos_items!$D:$D,$C$6) -> 0 | I40: =COUNTIFS(Datos_items!$L:$L,$A40,Datos_items!$AA:$AA,I$33,Datos_items!$E:$E,$C$4,Datos_items!$C:$C,$C$5,Datos_items!$D:$D,$C$6) -> 0 | J40: =COUNTIFS(Datos_items!$L:$L,$A40,Datos_items!$AA:$AA,J$33,Datos_items!$E:$E,$C$4,Datos_items!$C:$C,$C$5,Datos_items!$D:$D,$C$6) -> 0 | K40: =COUNTIFS(Datos_items!$L:$L,$A40,Datos_items!$AA:$AA,K$33,Datos_items!$E:$E,$C$4,Datos_items!$C:$C,$C$5,Datos_items!$D:$D,$C$6) -> 0 | L40: =COUNTIFS(Datos_items!$L:$L,$A40,Datos_items!$AA:$AA,L$33,Datos_items!$E:$E,$C$4,Datos_items!$C:$C,$C$5,Datos_items!$D:$D,$C$6) -> 0 | M40: =COUNTIFS(Datos_items!$L:$L,$A40,Datos_items!$AA:$AA,M$33,Datos_items!$E:$E,$C$4,Datos_items!$C:$C,$C$5,Datos_items!$D:$D,$C$6) -> 0 | ... X40: =COUNTIFS(Datos_items!$L:$L,$A40,Datos_items!$AA:$AA,X$33,Datos_items!$E:$E,$C$4,Datos_items!$C:$C,$C$5,Datos_items!$D:$D,$C$6) -> 0
A41: Po | B41: C2 | C41: =COUNTIFS(Datos_items!$L:$L,$A41,Datos_items!$E:$E,$C$4,Datos_items!$C:$C,$C$5,Datos_items!$D:$D,$C$6) -> 0 | D41: =IFERROR(SUMIFS(Datos_items!$Z:$Z,Datos_items!$L:$L,$A41,Datos_items!$E:$E,$C$4,Datos_items!$C:$C,$C$5,Datos_items!$D:$D,$C$6)/C41,"") | E41: =IF(MAX(F41:X41)=0,"",INDEX($F$33:$X$33,MATCH(MAX(F41:X41),F41:X41,0))) | F41: =COUNTIFS(Datos_items!$L:$L,$A41,Datos_items!$AA:$AA,F$33,Datos_items!$E:$E,$C$4,Datos_items!$C:$C,$C$5,Datos_items!$D:$D,$C$6) -> 0 | G41: =COUNTIFS(Datos_items!$L:$L,$A41,Datos_items!$AA:$AA,G$33,Datos_items!$E:$E,$C$4,Datos_items!$C:$C,$C$5,Datos_items!$D:$D,$C$6) -> 0 | H41: =COUNTIFS(Datos_items!$L:$L,$A41,Datos_items!$AA:$AA,H$33,Datos_items!$E:$E,$C$4,Datos_items!$C:$C,$C$5,Datos_items!$D:$D,$C$6) -> 0 | I41: =COUNTIFS(Datos_items!$L:$L,$A41,Datos_items!$AA:$AA,I$33,Datos_items!$E:$E,$C$4,Datos_items!$C:$C,$C$5,Datos_items!$D:$D,$C$6) -> 0 | J41: =COUNTIFS(Datos_items!$L:$L,$A41,Datos_items!$AA:$AA,J$33,Datos_items!$E:$E,$C$4,Datos_items!$C:$C,$C$5,Datos_items!$D:$D,$C$6) -> 0 | K41: =COUNTIFS(Datos_items!$L:$L,$A41,Datos_items!$AA:$AA,K$33,Datos_items!$E:$E,$C$4,Datos_items!$C:$C,$C$5,Datos_items!$D:$D,$C$6) -> 0 | L41: =COUNTIFS(Datos_items!$L:$L,$A41,Datos_items!$AA:$AA,L$33,Datos_items!$E:$E,$C$4,Datos_items!$C:$C,$C$5,Datos_items!$D:$D,$C$6) -> 0 | M41: =COUNTIFS(Datos_items!$L:$L,$A41,Datos_items!$AA:$AA,M$33,Datos_items!$E:$E,$C$4,Datos_items!$C:$C,$C$5,Datos_items!$D:$D,$C$6) -> 0 | ... X41: =COUNTIFS(Datos_items!$L:$L,$A41,Datos_items!$AA:$AA,X$33,Datos_items!$E:$E,$C$4,Datos_items!$C:$C,$C$5,Datos_items!$D:$D,$C$6) -> 0
A42: Pk | B42: C2 | C42: =COUNTIFS(Datos_items!$L:$L,$A42,Datos_items!$E:$E,$C$4,Datos_items!$C:$C,$C$5,Datos_items!$D:$D,$C$6) -> 0 | D42: =IFERROR(SUMIFS(Datos_items!$Z:$Z,Datos_items!$L:$L,$A42,Datos_items!$E:$E,$C$4,Datos_items!$C:$C,$C$5,Datos_items!$D:$D,$C$6)/C42,"") | E42: =IF(MAX(F42:X42)=0,"",INDEX($F$33:$X$33,MATCH(MAX(F42:X42),F42:X42,0))) | F42: =COUNTIFS(Datos_items!$L:$L,$A42,Datos_items!$AA:$AA,F$33,Datos_items!$E:$E,$C$4,Datos_items!$C:$C,$C$5,Datos_items!$D:$D,$C$6) -> 0 | G42: =COUNTIFS(Datos_items!$L:$L,$A42,Datos_items!$AA:$AA,G$33,Datos_items!$E:$E,$C$4,Datos_items!$C:$C,$C$5,Datos_items!$D:$D,$C$6) -> 0 | H42: =COUNTIFS(Datos_items!$L:$L,$A42,Datos_items!$AA:$AA,H$33,Datos_items!$E:$E,$C$4,Datos_items!$C:$C,$C$5,Datos_items!$D:$D,$C$6) -> 0 | I42: =COUNTIFS(Datos_items!$L:$L,$A42,Datos_items!$AA:$AA,I$33,Datos_items!$E:$E,$C$4,Datos_items!$C:$C,$C$5,Datos_items!$D:$D,$C$6) -> 0 | J42: =COUNTIFS(Datos_items!$L:$L,$A42,Datos_items!$AA:$AA,J$33,Datos_items!$E:$E,$C$4,Datos_items!$C:$C,$C$5,Datos_items!$D:$D,$C$6) -> 0 | K42: =COUNTIFS(Datos_items!$L:$L,$A42,Datos_items!$AA:$AA,K$33,Datos_items!$E:$E,$C$4,Datos_items!$C:$C,$C$5,Datos_items!$D:$D,$C$6) -> 0 | L42: =COUNTIFS(Datos_items!$L:$L,$A42,Datos_items!$AA:$AA,L$33,Datos_items!$E:$E,$C$4,Datos_items!$C:$C,$C$5,Datos_items!$D:$D,$C$6) -> 0 | M42: =COUNTIFS(Datos_items!$L:$L,$A42,Datos_items!$AA:$AA,M$33,Datos_items!$E:$E,$C$4,Datos_items!$C:$C,$C$5,Datos_items!$D:$D,$C$6) -> 0 | ... X42: =COUNTIFS(Datos_items!$L:$L,$A42,Datos_items!$AA:$AA,X$33,Datos_items!$E:$E,$C$4,Datos_items!$C:$C,$C$5,Datos_items!$D:$D,$C$6) -> 0
A43: h1u | B43: C3 | C43: =COUNTIFS(Datos_items!$L:$L,$A43,Datos_items!$E:$E,$C$4,Datos_items!$C:$C,$C$5,Datos_items!$D:$D,$C$6) -> 0 | D43: =IFERROR(SUMIFS(Datos_items!$Z:$Z,Datos_items!$L:$L,$A43,Datos_items!$E:$E,$C$4,Datos_items!$C:$C,$C$5,Datos_items!$D:$D,$C$6)/C43,"") | E43: =IF(MAX(F43:X43)=0,"",INDEX($F$33:$X$33,MATCH(MAX(F43:X43),F43:X43,0))) | F43: =COUNTIFS(Datos_items!$L:$L,$A43,Datos_items!$AA:$AA,F$33,Datos_items!$E:$E,$C$4,Datos_items!$C:$C,$C$5,Datos_items!$D:$D,$C$6) -> 0 | G43: =COUNTIFS(Datos_items!$L:$L,$A43,Datos_items!$AA:$AA,G$33,Datos_items!$E:$E,$C$4,Datos_items!$C:$C,$C$5,Datos_items!$D:$D,$C$6) -> 0 | H43: =COUNTIFS(Datos_items!$L:$L,$A43,Datos_items!$AA:$AA,H$33,Datos_items!$E:$E,$C$4,Datos_items!$C:$C,$C$5,Datos_items!$D:$D,$C$6) -> 0 | I43: =COUNTIFS(Datos_items!$L:$L,$A43,Datos_items!$AA:$AA,I$33,Datos_items!$E:$E,$C$4,Datos_items!$C:$C,$C$5,Datos_items!$D:$D,$C$6) -> 0 | J43: =COUNTIFS(Datos_items!$L:$L,$A43,Datos_items!$AA:$AA,J$33,Datos_items!$E:$E,$C$4,Datos_items!$C:$C,$C$5,Datos_items!$D:$D,$C$6) -> 0 | K43: =COUNTIFS(Datos_items!$L:$L,$A43,Datos_items!$AA:$AA,K$33,Datos_items!$E:$E,$C$4,Datos_items!$C:$C,$C$5,Datos_items!$D:$D,$C$6) -> 0 | L43: =COUNTIFS(Datos_items!$L:$L,$A43,Datos_items!$AA:$AA,L$33,Datos_items!$E:$E,$C$4,Datos_items!$C:$C,$C$5,Datos_items!$D:$D,$C$6) -> 0 | M43: =COUNTIFS(Datos_items!$L:$L,$A43,Datos_items!$AA:$AA,M$33,Datos_items!$E:$E,$C$4,Datos_items!$C:$C,$C$5,Datos_items!$D:$D,$C$6) -> 0 | ... X43: =COUNTIFS(Datos_items!$L:$L,$A43,Datos_items!$AA:$AA,X$33,Datos_items!$E:$E,$C$4,Datos_items!$C:$C,$C$5,Datos_items!$D:$D,$C$6) -> 0
A44: h1 | B44: C3 | C44: =COUNTIFS(Datos_items!$L:$L,$A44,Datos_items!$E:$E,$C$4,Datos_items!$C:$C,$C$5,Datos_items!$D:$D,$C$6) -> 0 | D44: =IFERROR(SUMIFS(Datos_items!$Z:$Z,Datos_items!$L:$L,$A44,Datos_items!$E:$E,$C$4,Datos_items!$C:$C,$C$5,Datos_items!$D:$D,$C$6)/C44,"") | E44: =IF(MAX(F44:X44)=0,"",INDEX($F$33:$X$33,MATCH(MAX(F44:X44),F44:X44,0))) | F44: =COUNTIFS(Datos_items!$L:$L,$A44,Datos_items!$AA:$AA,F$33,Datos_items!$E:$E,$C$4,Datos_items!$C:$C,$C$5,Datos_items!$D:$D,$C$6) -> 0 | G44: =COUNTIFS(Datos_items!$L:$L,$A44,Datos_items!$AA:$AA,G$33,Datos_items!$E:$E,$C$4,Datos_items!$C:$C,$C$5,Datos_items!$D:$D,$C$6) -> 0 | H44: =COUNTIFS(Datos_items!$L:$L,$A44,Datos_items!$AA:$AA,H$33,Datos_items!$E:$E,$C$4,Datos_items!$C:$C,$C$5,Datos_items!$D:$D,$C$6) -> 0 | I44: =COUNTIFS(Datos_items!$L:$L,$A44,Datos_items!$AA:$AA,I$33,Datos_items!$E:$E,$C$4,Datos_items!$C:$C,$C$5,Datos_items!$D:$D,$C$6) -> 0 | J44: =COUNTIFS(Datos_items!$L:$L,$A44,Datos_items!$AA:$AA,J$33,Datos_items!$E:$E,$C$4,Datos_items!$C:$C,$C$5,Datos_items!$D:$D,$C$6) -> 0 | K44: =COUNTIFS(Datos_items!$L:$L,$A44,Datos_items!$AA:$AA,K$33,Datos_items!$E:$E,$C$4,Datos_items!$C:$C,$C$5,Datos_items!$D:$D,$C$6) -> 0 | L44: =COUNTIFS(Datos_items!$L:$L,$A44,Datos_items!$AA:$AA,L$33,Datos_items!$E:$E,$C$4,Datos_items!$C:$C,$C$5,Datos_items!$D:$D,$C$6) -> 0 | M44: =COUNTIFS(Datos_items!$L:$L,$A44,Datos_items!$AA:$AA,M$33,Datos_items!$E:$E,$C$4,Datos_items!$C:$C,$C$5,Datos_items!$D:$D,$C$6) -> 0 | ... X44: =COUNTIFS(Datos_items!$L:$L,$A44,Datos_items!$AA:$AA,X$33,Datos_items!$E:$E,$C$4,Datos_items!$C:$C,$C$5,Datos_items!$D:$D,$C$6) -> 0
...

Sheet Por_alumno
A1: Resultados por estudiante
A2: Calificaciones solo de modo Evaluación. Los aciertos por competencia y los errores respetan el filtro «Modo» de Analisis_grupo.
A4: # | B4: Matrícula | C4: Nombre | D4: Grupo | E4: Problemas en evaluación | F4: Promedio evaluaciones | G4: Promedio diagnóstico | H4: Promedio final | I4: Ganancia normalizada | J4: C1 | K4: C2 | L4: C3 | M4: C4 | N4: C5 | O4: C6 | P4: C7 | Q4: C8 | R4: Competencia más débil | S4: Competencias bajo umbral | T4: LEC | U4: CAL | V4: ARR | W4: SR | X4: OTR | Y4: E01 | Z4: E02 | AA4: E03 | AB4: E04 | AC4: E05 | AD4: E06 | AE4: E07 | AF4: E08 | AG4: E09 | AH4: E10 | AI4: E11 | AJ4: E12 | AK4: E13 | AL4: E14 | AM4: Error conceptual más frecuente | AN4: Problemas practicados | AO4: Pistas vistas | AP4: Soluciones consultadas
A5: 1 | B5: =IFERROR(INDEX(Datos_problemas!$B:$B,MATCH($A5,Datos_problemas!$AV:$AV,0)),"") | C5: =IF($B5="","",INDEX(Datos_problemas!$C:$C,MATCH($A5,Datos_problemas!$AV:$AV,0))) | D5: =IF($B5="","",INDEX(Datos_problemas!$D:$D,MATCH($A5,Datos_problemas!$AV:$AV,0))) | E5: =IF($B5="","",COUNTIFS(Datos_problemas!$B:$B,$B5,Datos_problemas!$F:$F,"Evaluación")) | F5: =IF($B5="","",IFERROR(AVERAGEIFS(Datos_problemas!$AE:$AE,Datos_problemas!$B:$B,$B5,Datos_problemas!$F:$F,"Evaluación"),"")) | G5: =IF($B5="","",IFERROR(AVERAGEIFS(Datos_problemas!$AE:$AE,Datos_problemas!$B:$B,$B5,Datos_problemas!$F:$F,"Evaluación",Datos_problemas!$E:$E,"Diagnóstico"),"")) | H5: =IF($B5="","",IFERROR(AVERAGEIFS(Datos_problemas!$AE:$AE,Datos_problemas!$B:$B,$B5,Datos_problemas!$F:$F,"Evaluación",Datos_problemas!$E:$E,"Final"),"")) | I5: =IF(OR(G5="",H5=""),"",IF(G5>=10,"",(H5-G5)/(10-G5))) | J5: =IF($B5="","",IFERROR(SUMIFS(Datos_items!$Z:$Z,Datos_items!$B:$B,$B5,Datos_items!$O:$O,J$4,Datos_items!$E:$E,Analisis_grupo!$C$4)/COUNTIFS(Datos_items!$B:$B,$B5,Datos_items!$O:$O,J$4,Datos_items!$E:$E,Analisis_grupo!$C$4),"")) | K5: =IF($B5="","",IFERROR(SUMIFS(Datos_items!$Z:$Z,Datos_items!$B:$B,$B5,Datos_items!$O:$O,K$4,Datos_items!$E:$E,Analisis_grupo!$C$4)/COUNTIFS(Datos_items!$B:$B,$B5,Datos_items!$O:$O,K$4,Datos_items!$E:$E,Analisis_grupo!$C$4),"")) | L5: =IF($B5="","",IFERROR(SUMIFS(Datos_items!$Z:$Z,Datos_items!$B:$B,$B5,Datos_items!$O:$O,L$4,Datos_items!$E:$E,Analisis_grupo!$C$4)/COUNTIFS(Datos_items!$B:$B,$B5,Datos_items!$O:$O,L$4,Datos_items!$E:$E,Analisis_grupo!$C$4),"")) | M5: =IF($B5="","",IFERROR(SUMIFS(Datos_items!$Z:$Z,Datos_items!$B:$B,$B5,Datos_items!$O:$O,M$4,Datos_items!$E:$E,Analisis_grupo!$C$4)/COUNTIFS(Datos_items!$B:$B,$B5,Datos_items!$O:$O,M$4,Datos_items!$E:$E,Analisis_grupo!$C$4),"")) | N5: =IF($B5="","",IFERROR(SUMIFS(Datos_items!$Z:$Z,Datos_items!$B:$B,$B5,Datos_items!$O:$O,N$4,Datos_items!$E:$E,Analisis_grupo!$C$4)/COUNTIFS(Datos_items!$B:$B,$B5,Datos_items!$O:$O,N$4,Datos_items!$E:$E,Analisis_grupo!$C$4),"")) | O5: =IF($B5="","",IFERROR(SUMIFS(Datos_items!$Z:$Z,Datos_items!$B:$B,$B5,Datos_items!$O:$O,O$4,Datos_items!$E:$E,Analisis_grupo!$C$4)/COUNTIFS(Datos_items!$B:$B,$B5,Datos_items!$O:$O,O$4,Datos_items!$E:$E,Analisis_grupo!$C$4),"")) | P5: =IF($B5="","",IFERROR(SUMIFS(Datos_items!$Z:$Z,Datos_items!$B:$B,$B5,Datos_items!$O:$O,P$4,Datos_items!$E:$E,Analisis_grupo!$C$4)/COUNTIFS(Datos_items!$B:$B,$B5,Datos_items!$O:$O,P$4,Datos_items!$E:$E,Analisis_grupo!$C$4),"")) | Q5: =IF($B5="","",IFERROR(SUMIFS(Datos_items!$Z:$Z,Datos_items!$B:$B,$B5,Datos_items!$O:$O,Q$4,Datos_items!$E:$E,Analisis_grupo!$C$4)/COUNTIFS(Datos_items!$B:$B,$B5,Datos_items!$O:$O,Q$4,Datos_items!$E:$E,Analisis_grupo!$C$4),"")) | R5: =IF(COUNT(J5:Q5)=0,"",IF(MIN(J5:Q5)>=Analisis_grupo!$B$7,"(ninguna)",INDEX($J$4:$Q$4,MATCH(MIN(J5:Q5),J5:Q5,0)))) | S5: =IF($B5="","",COUNTIF(J5:Q5,"<"&Analisis_grupo!$B$7)) | T5: =IF($B5="","",COUNTIFS(Datos_items!$B:$B,$B5,Datos_items!$AA:$AA,T$4,Datos_items!$E:$E,Analisis_grupo!$C$4)) | U5: =IF($B5="","",COUNTIFS(Datos_items!$B:$B,$B5,Datos_items!$AA:$AA,U$4,Datos_items!$E:$E,Analisis_grupo!$C$4)) | V5: =IF($B5="","",COUNTIFS(Datos_items!$B:$B,$B5,Datos_items!$AA:$AA,V$4,Datos_items!$E:$E,Analisis_grupo!$C$4)) | W5: =IF($B5="","",COUNTIFS(Datos_items!$B:$B,$B5,Datos_items!$AA:$AA,W$4,Datos_items!$E:$E,Analisis_grupo!$C$4)) | X5: =IF($B5="","",COUNTIFS(Datos_items!$B:$B,$B5,Datos_items!$AA:$AA,X$4,Datos_items!$E:$E,Analisis_grupo!$C$4)) | Y5: =IF($B5="","",COUNTIFS(Datos_items!$B:$B,$B5,Datos_items!$AA:$AA,Y$4,Datos_items!$E:$E,Analisis_grupo!$C$4)) | Z5: =IF($B5="","",COUNTIFS(Datos_items!$B:$B,$B5,Datos_items!$AA:$AA,Z$4,Datos_items!$E:$E,Analisis_grupo!$C$4)) | AA5: =IF($B5="","",COUNTIFS(Datos_items!$B:$B,$B5,Datos_items!$AA:$AA,AA$4,Datos_items!$E:$E,Analisis_grupo!$C$4)) | ... AL5: =IF($B5="","",COUNTIFS(Datos_items!$B:$B,$B5,Datos_items!$AA:$AA,AL$4,Datos_items!$E:$E,Analisis_grupo!$C$4)) | AM5: =IF($B5="","",IF(MAX(Y5:AL5)=0,"",INDEX($Y$4:$AL$4,MATCH(MAX(Y5:AL5),Y5:AL5,0)))) | AN5: =IF($B5="","",COUNTIFS(Datos_problemas!$B:$B,$B5,Datos_problemas!$F:$F,"Práctica")) | AO5: =IF($B5="","",SUMIFS(Datos_problemas!$AQ:$AQ,Datos_problemas!$B:$B,$B5,Datos_problemas!$F:$F,"Práctica")) | AP5: =IF($B5="","",COUNTIFS(Datos_problemas!$B:$B,$B5,Datos_problemas!$F:$F,"Práctica",Datos_problemas!$AS:$AS,"Sí"))
A6: 2 | B6: =IFERROR(INDEX(Datos_problemas!$B:$B,MATCH($A6,Datos_problemas!$AV:$AV,0)),"") | C6: =IF($B6="","",INDEX(Datos_problemas!$C:$C,MATCH($A6,Datos_problemas!$AV:$AV,0))) | D6: =IF($B6="","",INDEX(Datos_problemas!$D:$D,MATCH($A6,Datos_problemas!$AV:$AV,0))) | E6: =IF($B6="","",COUNTIFS(Datos_problemas!$B:$B,$B6,Datos_problemas!$F:$F,"Evaluación")) | F6: =IF($B6="","",IFERROR(AVERAGEIFS(Datos_problemas!$AE:$AE,Datos_problemas!$B:$B,$B6,Datos_problemas!$F:$F,"Evaluación"),"")) | G6: =IF($B6="","",IFERROR(AVERAGEIFS(Datos_problemas!$AE:$AE,Datos_problemas!$B:$B,$B6,Datos_problemas!$F:$F,"Evaluación",Datos_problemas!$E:$E,"Diagnóstico"),"")) | H6: =IF($B6="","",IFERROR(AVERAGEIFS(Datos_problemas!$AE:$AE,Datos_problemas!$B:$B,$B6,Datos_problemas!$F:$F,"Evaluación",Datos_problemas!$E:$E,"Final"),"")) | I6: =IF(OR(G6="",H6=""),"",IF(G6>=10,"",(H6-G6)/(10-G6))) | J6: =IF($B6="","",IFERROR(SUMIFS(Datos_items!$Z:$Z,Datos_items!$B:$B,$B6,Datos_items!$O:$O,J$4,Datos_items!$E:$E,Analisis_grupo!$C$4)/COUNTIFS(Datos_items!$B:$B,$B6,Datos_items!$O:$O,J$4,Datos_items!$E:$E,Analisis_grupo!$C$4),"")) | K6: =IF($B6="","",IFERROR(SUMIFS(Datos_items!$Z:$Z,Datos_items!$B:$B,$B6,Datos_items!$O:$O,K$4,Datos_items!$E:$E,Analisis_grupo!$C$4)/COUNTIFS(Datos_items!$B:$B,$B6,Datos_items!$O:$O,K$4,Datos_items!$E:$E,Analisis_grupo!$C$4),"")) | L6: =IF($B6="","",IFERROR(SUMIFS(Datos_items!$Z:$Z,Datos_items!$B:$B,$B6,Datos_items!$O:$O,L$4,Datos_items!$E:$E,Analisis_grupo!$C$4)/COUNTIFS(Datos_items!$B:$B,$B6,Datos_items!$O:$O,L$4,Datos_items!$E:$E,Analisis_grupo!$C$4),"")) | M6: =IF($B6="","",IFERROR(SUMIFS(Datos_items!$Z:$Z,Datos_items!$B:$B,$B6,Datos_items!$O:$O,M$4,Datos_items!$E:$E,Analisis_grupo!$C$4)/COUNTIFS(Datos_items!$B:$B,$B6,Datos_items!$O:$O,M$4,Datos_items!$E:$E,Analisis_grupo!$C$4),"")) | N6: =IF($B6="","",IFERROR(SUMIFS(Datos_items!$Z:$Z,Datos_items!$B:$B,$B6,Datos_items!$O:$O,N$4,Datos_items!$E:$E,Analisis_grupo!$C$4)/COUNTIFS(Datos_items!$B:$B,$B6,Datos_items!$O:$O,N$4,Datos_items!$E:$E,Analisis_grupo!$C$4),"")) | O6: =IF($B6="","",IFERROR(SUMIFS(Datos_items!$Z:$Z,Datos_items!$B:$B,$B6,Datos_items!$O:$O,O$4,Datos_items!$E:$E,Analisis_grupo!$C$4)/COUNTIFS(Datos_items!$B:$B,$B6,Datos_items!$O:$O,O$4,Datos_items!$E:$E,Analisis_grupo!$C$4),"")) | P6: =IF($B6="","",IFERROR(SUMIFS(Datos_items!$Z:$Z,Datos_items!$B:$B,$B6,Datos_items!$O:$O,P$4,Datos_items!$E:$E,Analisis_grupo!$C$4)/COUNTIFS(Datos_items!$B:$B,$B6,Datos_items!$O:$O,P$4,Datos_items!$E:$E,Analisis_grupo!$C$4),"")) | Q6: =IF($B6="","",IFERROR(SUMIFS(Datos_items!$Z:$Z,Datos_items!$B:$B,$B6,Datos_items!$O:$O,Q$4,Datos_items!$E:$E,Analisis_grupo!$C$4)/COUNTIFS(Datos_items!$B:$B,$B6,Datos_items!$O:$O,Q$4,Datos_items!$E:$E,Analisis_grupo!$C$4),"")) | R6: =IF(COUNT(J6:Q6)=0,"",IF(MIN(J6:Q6)>=Analisis_grupo!$B$7,"(ninguna)",INDEX($J$4:$Q$4,MATCH(MIN(J6:Q6),J6:Q6,0)))) | S6: =IF($B6="","",COUNTIF(J6:Q6,"<"&Analisis_grupo!$B$7)) | T6: =IF($B6="","",COUNTIFS(Datos_items!$B:$B,$B6,Datos_items!$AA:$AA,T$4,Datos_items!$E:$E,Analisis_grupo!$C$4)) | U6: =IF($B6="","",COUNTIFS(Datos_items!$B:$B,$B6,Datos_items!$AA:$AA,U$4,Datos_items!$E:$E,Analisis_grupo!$C$4)) | V6: =IF($B6="","",COUNTIFS(Datos_items!$B:$B,$B6,Datos_items!$AA:$AA,V$4,Datos_items!$E:$E,Analisis_grupo!$C$4)) | W6: =IF($B6="","",COUNTIFS(Datos_items!$B:$B,$B6,Datos_items!$AA:$AA,W$4,Datos_items!$E:$E,Analisis_grupo!$C$4)) | X6: =IF($B6="","",COUNTIFS(Datos_items!$B:$B,$B6,Datos_items!$AA:$AA,X$4,Datos_items!$E:$E,Analisis_grupo!$C$4)) | Y6: =IF($B6="","",COUNTIFS(Datos_items!$B:$B,$B6,Datos_items!$AA:$AA,Y$4,Datos_items!$E:$E,Analisis_grupo!$C$4)) | Z6: =IF($B6="","",COUNTIFS(Datos_items!$B:$B,$B6,Datos_items!$AA:$AA,Z$4,Datos_items!$E:$E,Analisis_grupo!$C$4)) | AA6: =IF($B6="","",COUNTIFS(Datos_items!$B:$B,$B6,Datos_items!$AA:$AA,AA$4,Datos_items!$E:$E,Analisis_grupo!$C$4)) | ... AL6: =IF($B6="","",COUNTIFS(Datos_items!$B:$B,$B6,Datos_items!$AA:$AA,AL$4,Datos_items!$E:$E,Analisis_grupo!$C$4)) | AM6: =IF($B6="","",IF(MAX(Y6:AL6)=0,"",INDEX($Y$4:$AL$4,MATCH(MAX(Y6:AL6),Y6:AL6,0)))) | AN6: =IF($B6="","",COUNTIFS(Datos_problemas!$B:$B,$B6,Datos_problemas!$F:$F,"Práctica")) | AO6: =IF($B6="","",SUMIFS(Datos_problemas!$AQ:$AQ,Datos_problemas!$B:$B,$B6,Datos_problemas!$F:$F,"Práctica")) | AP6: =IF($B6="","",COUNTIFS(Datos_problemas!$B:$B,$B6,Datos_problemas!$F:$F,"Práctica",Datos_problemas!$AS:$AS,"Sí"))
